<?xml version="1.0" ?>
<robot name="test_robot">
	<link name="world"/>
	<joint name="world_joint" type="fixed">
		<parent link="world"/>
		<child link="base_rail_link"/>
		<origin xyz="0.0 0.0 0.0" rpy="0.0 0.0 0.0"/>
		<axis xyz="0 0 1"/>
		<limit effort="100.0" lower="-3.141592653589793" upper="3.141592653589793" velocity="1.0"/>
		<dynamics damping="0.0" friction="0.0"/>
	</joint>
	<link name="base_rail_link">
		<visual>
			<geometry>
				<mesh filename="mesh/base_rail_link.stl"/>
			</geometry>
		</visual>
		<collision>
			<geometry>
				<mesh filename="collision/base_rail_link_col.stl"/>
			</geometry>
		</collision>
		<inertial>
			<mass value="1.0"/>
			<inertia ixx="0.0" ixy="0.0" ixz="0.0" iyy="0.0" iyz="0.0" izz="0.0"/>
		</inertial>
	</link>
	<joint name="joint_01" type="prismatic">
		<parent link="base_rail_link"/>
		<child link="link_01"/>
		<origin xyz="0.0 0.0 0.375" rpy="0.0 0.0 0.0"/>
		<axis xyz="0 1 0"/>
		<limit effort="100.0" lower="-3.141592653589793" upper="3.141592653589793" velocity="1.0"/>
		<dynamics damping="0.0" friction="0.0"/>
	</joint>
	<link name="link_01">
		<visual>
			<geometry>
				<mesh filename="mesh/link_01.stl"/>
			</geometry>
		</visual>
		<collision>
			<geometry>
				<mesh filename="collision/link_01_col.stl"/>
			</geometry>
		</collision>
		<inertial>
			<mass value="1.0"/>
			<inertia ixx="0.0" ixy="0.0" ixz="0.0" iyy="0.0" iyz="0.0" izz="0.0"/>
		</inertial>
	</link>
	<joint name="joint_02" type="revolute">
		<parent link="link_01"/>
		<child link="link_02"/>
		<origin xyz="0.0 1.0 0.0" rpy="0 0 0"/>
		<axis xyz="0 0 1"/>
		<limit effort="100.0" lower="-3.141592653589793" upper="3.141592653589793" velocity="1.0"/>
		<dynamics damping="0.0" friction="0.0"/>
	</joint>
	<link name="link_02">
		<visual>
			<geometry>
				<mesh filename="mesh/link_02.stl"/>
			</geometry>
		</visual>
		<collision>
			<geometry>
				<mesh filename="collision/link_02_col.stl"/>
			</geometry>
		</collision>
		<inertial>
			<mass value="1.0"/>
			<inertia ixx="0.0" ixy="0.0" ixz="0.0" iyy="0.0" iyz="0.0" izz="0.0"/>
		</inertial>
	</link>
	<joint name="joint_03" type="revolute">
		<parent link="link_02"/>
		<child link="link_03"/>
		<origin xyz="0.0 1.41 0.0" rpy="0 0 0"/>
		<axis xyz="0 0 1"/>
		<limit effort="100.0" lower="-3.141592653589793" upper="3.141592653589793" velocity="1.0"/>
		<dynamics damping="0.0" friction="0.0"/>
	</joint>
	<link name="link_03">
		<visual>
			<geometry>
				<mesh filename="mesh/link_03.stl"/>
			</geometry>
		</visual>
		<collision>
			<geometry>
				<mesh filename="collision/link_03_col.stl"/>
			</geometry>
		</collision>
		<inertial>
			<mass value="1.0"/>
			<inertia ixx="0.0" ixy="0.0" ixz="0.0" iyy="0.0" iyz="0.0" izz="0.0"/>
		</inertial>
	</link>
	<joint name="joint_04" type="revolute">
		<parent link="link_03"/>
		<child link="link_04"/>
		<origin xyz="0.0 1.13 0.0" rpy="0 0 0"/>
		<axis xyz="0 1 0"/>
		<limit effort="100.0" lower="-3.141592653589793" upper="3.141592653589793" velocity="1.0"/>
		<dynamics damping="0.0" friction="0.0"/>
	</joint>
	<link name="link_04">
		<visual>
			<geometry>
				<mesh filename="mesh/link_04.stl"/>
			</geometry>
		</visual>
		<collision>
			<geometry>
				<mesh filename="collision/link_04_col.stl"/>
			</geometry>
		</collision>
		<inertial>
			<mass value="1.0"/>
			<inertia ixx="0.0" ixy="0.0" ixz="0.0" iyy="0.0" iyz="0.0" izz="0.0"/>
		</inertial>
	</link>
	<joint name="joint_05" type="revolute">
		<parent link="link_04"/>
		<child link="link_05"/>
		<origin xyz="0.0 0.565257 0.356751" rpy="0.0 0.0 3.141592653589793"/>
		<axis xyz="1 0 0"/>
		<limit effort="100.0" lower="-3.141592653589793" upper="3.141592653589793" velocity="1.0"/>
		<dynamics damping="0.0" friction="0.0"/>
	</joint>
	<link name="link_05">
		<visual>
			<geometry>
				<mesh filename="mesh/link_05.stl"/>
			</geometry>
		</visual>
		<collision>
			<geometry>
				<mesh filename="collision/link_05_col.stl"/>
			</geometry>
		</collision>
		<inertial>
			<mass value="1.0"/>
			<inertia ixx="0.0" ixy="0.0" ixz="0.0" iyy="0.0" iyz="0.0" izz="0.0"/>
		</inertial>
	</link>
	<joint name="joint_06" type="revolute">
		<parent link="link_05"/>
		<child link="link_06"/>
		<origin xyz="0.0 0.86 0.39" rpy="0 0 0"/>
		<axis xyz="0 1 0"/>
		<limit effort="100.0" lower="-3.141592653589793" upper="3.141592653589793" velocity="1.0"/>
		<dynamics damping="0.0" friction="0.0"/>
	</joint>
	<link name="link_06">
		<visual>
			<geometry>
				<mesh filename="mesh/link_06.stl"/>
			</geometry>
		</visual>
		<collision>
			<geometry>
				<mesh filename="collision/link_06_col.stl"/>
			</geometry>
		</collision>
		<inertial>
			<mass value="1.0"/>
			<inertia ixx="0.0" ixy="0.0" ixz="0.0" iyy="0.0" iyz="0.0" izz="0.0"/>
		</inertial>
	</link>
	<joint name="joint_07" type="revolute">
		<parent link="link_06"/>
		<child link="link_07"/>
		<origin xyz="0.0 1.175 0.0" rpy="0 0 0"/>
		<axis xyz="0 0 1"/>
		<limit effort="100.0" lower="-3.141592653589793" upper="3.141592653589793" velocity="1.0"/>
		<dynamics damping="0.0" friction="0.0"/>
	</joint>
	<link name="link_07">
		<visual>
			<geometry>
				<mesh filename="mesh/link_07.stl"/>
			</geometry>
		</visual>
		<collision>
			<geometry>
				<mesh filename="collision/link_07_col.stl"/>
			</geometry>
		</collision>
		<inertial>
			<mass value="1.0"/>
			<inertia ixx="0.0" ixy="0.0" ixz="0.0" iyy="0.0" iyz="0.0" izz="0.0"/>
		</inertial>
	</link>
	<joint name="joint_08" type="revolute">
		<parent link="link_07"/>
		<child link="link_08"/>
		<origin xyz="0.0 0.62 0.0" rpy="0 0 0"/>
		<axis xyz="0 1 0"/>
		<limit effort="100.0" lower="-3.141592653589793" upper="3.141592653589793" velocity="1.0"/>
		<dynamics damping="0.0" friction="0.0"/>
	</joint>
	<link name="link_08">
		<visual>
			<geometry>
				<mesh filename="mesh/link_08.stl"/>
			</geometry>
		</visual>
		<collision>
			<geometry>
				<mesh filename="collision/link_08_col.stl"/>
			</geometry>
		</collision>
		<inertial>
			<mass value="1.0"/>
			<inertia ixx="0.0" ixy="0.0" ixz="0.0" iyy="0.0" iyz="0.0" izz="0.0"/>
		</inertial>
	</link>
	<joint name="joint_09" type="revolute">
		<parent link="link_08"/>
		<child link="link_09"/>
		<origin xyz="0.0 0.68 0.2" rpy="-1.5707963267948966 0.0 0.0"/>
		<axis xyz="1 0 0"/>
		<limit effort="100.0" lower="-3.141592653589793" upper="3.141592653589793" velocity="1.0"/>
		<dynamics damping="0.0" friction="0.0"/>
	</joint>
	<link name="link_09">
		<visual>
			<geometry>
				<mesh filename="mesh/link_09.stl"/>
			</geometry>
		</visual>
		<collision>
			<geometry>
				<mesh filename="collision/link_09_col.stl"/>
			</geometry>
		</collision>
		<inertial>
			<mass value="1.0"/>
			<inertia ixx="0.0" ixy="0.0" ixz="0.0" iyy="0.0" iyz="0.0" izz="0.0"/>
		</inertial>
	</link>
	<joint name="joint_10" type="revolute">
		<parent link="link_09"/>
		<child link="link_10"/>
		<origin xyz="0.0 0.0 0.65" rpy="0.0 0.0 0.0"/>
		<axis xyz="0 0 1"/>
		<limit effort="100.0" lower="-3.141592653589793" upper="3.141592653589793" velocity="1.0"/>
		<dynamics damping="0.0" friction="0.0"/>
	</joint>
	<link name="link_10">
		<visual>
			<geometry>
				<mesh filename="mesh/link_10.stl"/>
			</geometry>
		</visual>
		<collision>
			<geometry>
				<mesh filename="collision/link_10_col.stl"/>
			</geometry>
		</collision>
		<inertial>
			<mass value="1.0"/>
			<inertia ixx="0.0" ixy="0.0" ixz="0.0" iyy="0.0" iyz="0.0" izz="0.0"/>
		</inertial>
	</link>
</robot>