<?xml version="1.0" encoding="utf-8"?>
<!-- This URDF was automatically created by SolidWorks to URDF Exporter! Originally created by Stephen Brawner (brawner@gmail.com) 
     Commit Version: 1.6.0-4-g7f85cfe  Build Version: 1.6.7995.38578
     For more information, please see http://wiki.ros.org/sw_urdf_exporter -->
<robot
  name="ivt_assem_kinema1">
  <link
    name="base_link">
    <visual>
      <origin
        xyz="0 0 0"
        rpy="0 0 0" />
      <geometry>
        <mesh
          filename="package://ivt_assem_kinema1/meshes/base_link.STL" />
      </geometry>
      <material
        name="">
        <color
          rgba="0.50 0.50 0.50 1" />
      </material>
    </visual>
    <collision>
      <origin
        xyz="0 0 0"
        rpy="0 0 0" />
      <geometry>
        <mesh
          filename="package://ivt_assem_kinema1/meshes/base_link.STL" />
      </geometry>
    </collision>
  </link>
  <link
    name="L1(VF1)">
    <inertial>
      <origin
        xyz="4.27831464623006 4.44063358373303 0.567053775933844"
        rpy="0 0 0" />
      <mass
        value="3029" />
      <inertia
        ixx="31.3011766142758"
        ixy="-5.81956709496745"
        ixz="-0.143976227930554"
        iyy="28.9609722483631"
        iyz="-0.249855793533199"
        izz="24.868411986285" />
    </inertial>
    <visual>
      <origin
        xyz="0 0 0"
        rpy="0 0 0" />
      <geometry>
        <mesh
          filename="package://ivt_assem_kinema1/meshes/L1(VF1).STL" />
      </geometry>
      <material
        name="">
        <color
          rgba="0.098 0.471 0.71 1" />
      </material>
    </visual>
    <collision>
      <origin
        xyz="0 0 0"
        rpy="0 0 0" />
      <geometry>
        <mesh
          filename="package://ivt_assem_kinema1/meshes/L1(VF1).STL" />
      </geometry>
    </collision>
  </link>
  <joint
    name="J01"
    type="revolute">
    <origin
      xyz="0 0 0.476999949047664"
      rpy="0 0 0.846484687217196" />
      <!-- 0.846484687217196 rad = 48.5 deg -->
    <parent
      link="base_link" />
    <child
      link="L1(VF1)" />
    <axis
      xyz="0 0 1" />
    <!-- limit =  +37.5 deg, -36.5 deg =lower="-0.63702638888" upper="0.65447916666"-->
    <limit
      lower="-0.63702638888"
      upper="0.65447916666"
      effort="0"
      velocity="0" />
  </joint>
  <link
    name="L2(VF2)">
    <inertial>
      <origin
        xyz="-0.268964456058335 0.134081321025601 0.000543139120798175"
        rpy="0 0 0" />
      <mass
        value="1622" />
      <inertia
        ixx="30.0532876924675"
        ixy="-3.80754467632883"
        ixz="-0.00385395856089926"
        iyy="28.626808368015"
        iyz="-0.00436641602371218"
        izz="21.6951010956236" />
    </inertial>
    <visual>
      <origin
        xyz="0 0 0"
        rpy="0 0 0" />
      <geometry>
        <mesh
          filename="package://ivt_assem_kinema1/meshes/L2(VF2).STL" />
      </geometry>
      <material
        name="">
        <color
          rgba="1 0.502 0.024 1" />
      </material>
    </visual>
    <collision>
      <origin
        xyz="0 0 0"
        rpy="0 0 0" />
      <geometry>
        <mesh
          filename="package://ivt_assem_kinema1/meshes/L2(VF2).STL" />
      </geometry>
    </collision>
  </link>
  <joint
    name="J12"
    type="revolute">
    <origin
      xyz="3.97854409603429 4.74144421974917 0.543000050916989"
      rpy="0 0 0" />
    <parent
      link="L1(VF1)" />
    <child
      link="L2(VF2)" />
    <axis
      xyz="-0.766044443119437 0.642787609685992 0" />
    <limit
      lower="-2.79"
      upper="2.53"
      effort="0"
      velocity="0" />
      <!-- J12 in urdf generated by solidworks and DELMIA definition is not same axis direction.-->
     <!-- J12 in urdf generated by solidworks and DELMIA definition is not same axis direction.-->

      <!-- J12 original =   -160to145     lower="-2.79" upper="2.53"-->
  </joint>
  <link
    name="L3(TA-Drive)">
    <inertial>
      <origin
        xyz="-0.515421476796673 -0.387036684241834 0.19032824766254"
        rpy="0 0 0" />
      <mass
        value="1322" />
      <inertia
        ixx="22.7805058961668"
        ixy="-2.8534517293667"
        ixz="3.0437909889782"
        iyy="25.655497067829"
        iyz="3.04299840574883"
        izz="24.3983181745992" />
    </inertial>
    <visual>
      <origin
        xyz="0 0 0"
        rpy="0 0 0" />
      <geometry>
        <mesh
          filename="package://ivt_assem_kinema1/meshes/L3(TA-Drive).STL" />
      </geometry>
      <material
        name="">
        <color
          rgba="0.157 0.631 0.157 1" />
      </material>
    </visual>
    <collision>
      <origin
        xyz="0 0 0"
        rpy="0 0 0" />
      <geometry>
        <mesh
          filename="package://ivt_assem_kinema1/meshes/L3(TA-Drive).STL" />
      </geometry>
    </collision>
  </link>
  <joint
    name="J23"
    type="revolute">
    <origin
      xyz="-0.497363141943202 0.210436210876828 0"
      rpy="0 0 0" />
    <parent
      link="L2(VF2)" />
    <child
      link="L3(TA-Drive)" />
    <axis
      xyz="0.642787609686212 0.766044443119253 0" />
    <!-- original limit(-30to230):-0.52 to 4.01 -->
    <!-- extended limit(-180to230):-1.52 to 4.01 -->
    <!-- extended limit(-60to230):1.05 to 4.01 -->
    <!-- set to -360 deg to +360 deg -->
    <limit
      lower="-1.05"
      upper="4.01"
      effort="0"
      velocity="0" />
  </joint>
  <link
    name="L4(TA-ext)">
    <inertial>
      <origin
        xyz="2.8976008634218 4.37028853447607 1.35408667347657"
        rpy="0 0 0" />
      <mass
        value="1381" />
      <inertia
        ixx="544.275412275505"
        ixy="-4.45590518767136"
        ixz="0.0276382570364735"
        iyy="542.693621776818"
        iyz="0.259021029844838"
        izz="54.7771846932912" />
    </inertial>
    <visual>
      <origin
        xyz="0 0 0"
        rpy="0 0 0" />
      <geometry>
        <mesh
          filename="package://ivt_assem_kinema1/meshes/L4(TA-ext).STL" />
      </geometry>
      <material
        name="">
        <color
          rgba="0.843 0.133 0.137 1" />
      </material>
    </visual>
    <collision>
      <origin
        xyz="0 0 0"
        rpy="0 0 0" />
      <geometry>
        <mesh
          filename="package://ivt_assem_kinema1/meshes/L4(TA-ext).STL" />
      </geometry>
    </collision>
  </link>
  <joint
    name="J34"
    type="prismatic">
    <origin
      xyz="-3.47462853102528 -4.95820126998045 -0.356000000012616"
      rpy="0 0 0" />
    <parent
      link="L3(TA-Drive)" />
    <child
      link="L4(TA-ext)" />
    <axis
      xyz="0 0 1" />
    <limit
      lower="-1.4"
      upper="0"
      effort="0"
      velocity="0" />
  </joint>
  <link
    name="L5(TA-int)">
    <inertial>
      <origin
        xyz="2.95501007650385 4.42154199829884 1.04381171088123"
        rpy="0 0 0" />
      <mass
        value="656" />
      <inertia
        ixx="163.682312857059"
        ixy="1.83221368187769"
        ixz="-2.69399623450627"
        iyy="163.859587669375"
        iyz="4.10882870693169"
        izz="14.2342839970283" />
    </inertial>
    <visual>
      <origin
        xyz="0 0 0"
        rpy="0 0 0" />
      <geometry>
        <mesh
          filename="package://ivt_assem_kinema1/meshes/L5(TA-int).STL" />
      </geometry>
      <material
        name="">
        <color
          rgba="0.584 0.404 0.745 1" />
      </material>
    </visual>
    <collision>
      <origin
        xyz="0 0 0"
        rpy="0 0 0" />
      <geometry>
        <mesh
          filename="package://ivt_assem_kinema1/meshes/L5(TA-int).STL" />
      </geometry>
    </collision>
  </link>
  <joint
    name="J45"
    type="prismatic">
    <origin
      xyz="0 0 -0.293999999998152"
      rpy="0 0 0" />
    <parent
      link="L4(TA-ext)" />
    <child
      link="L5(TA-int)" />
    <axis
      xyz="0 0 1" />
    <limit
      lower="-1.35"
      upper="0"
      effort="0"
      velocity="0" />
  </joint>
  <link
    name="L6(EE-Frame)">
    <inertial>
      <origin
        xyz="0.00284691471720944 0.191098098179141 -0.276646108079727"
        rpy="0 0 0" />
      <mass
        value="826" />
      <inertia
        ixx="3.46097454250104"
        ixy="0.0100115287004395"
        ixz="0.0121909954030351"
        iyy="5.07987306064684"
        iyz="-0.154363483578792"
        izz="3.83794109222235" />
    </inertial>
    <visual>
      <origin
        xyz="0 0 0"
        rpy="0 0 0" />
      <geometry>
        <mesh
          filename="package://ivt_assem_kinema1/meshes/L6(EE-Frame).STL" />
      </geometry>
      <material
        name="">
        <color
          rgba="1 1 0 1" />
      </material>
    </visual>
    <collision>
      <origin
        xyz="0 0 0"
        rpy="0 0 0" />
      <geometry>
        <mesh
          filename="package://ivt_assem_kinema1/meshes/L6(EE-Frame).STL" />
      </geometry>
    </collision>
  </link>
  <joint
    name="J56"
    type="revolute">
    <origin
      xyz="3.00259508631999 4.38631890624998 0"
      rpy="0 0 -2.26892802912967" />
    <parent
      link="L5(TA-int)" />
    <child
      link="L6(EE-Frame)" />
    <axis
      xyz="0 0 1" />
    <limit
      lower="-3.1416"
      upper="3.1416"
      effort="0"
      velocity="0" />
  </joint>
  <link
    name="L7(EE-Tool)">
    <inertial>
      <origin
        xyz="-0.0509108002176816 -0.00404322702865034 -0.0587169379022555"
        rpy="0 0 0" />
      <mass
        value="334" />
      <inertia
        ixx="2.77740029838163"
        ixy="0.0420856303226253"
        ixz="0.4380872633446"
        iyy="2.5425499310199"
        iyz="-0.0644131456062198"
        izz="1.96318056189955" />
    </inertial>
    <visual>
      <origin
        xyz="0 0 0"
        rpy="0 0 0" />
      <geometry>
        <mesh
          filename="package://ivt_assem_kinema1/meshes/L7(EE-Tool).STL" />
      </geometry>
      <material
        name="">
        <color
          rgba="0 1 1 1" />
      </material>
    </visual>
    <collision>
      <origin
        xyz="0 0 0"
        rpy="0 0 0" />
      <geometry>
        <mesh
          filename="package://ivt_assem_kinema1/meshes/L7(EE-Tool).STL" />
      </geometry>
    </collision>
  </link>
  <joint
    name="J67"
    type="revolute">
    <origin
      xyz="0 0.209999861330641 -0.630000000000708"
      rpy="1.57079632679489 1.5707963267949 0" />
    <parent
      link="L6(EE-Frame)" />
    <child
      link="L7(EE-Tool)" />
    <axis
      xyz="0 1 0" />
    <limit
      lower="-1.6581"
      upper="0.087267"
      effort="0"
      velocity="0" />
  </joint>
  <link
    name="L8(EE-TC)">
    <inertial>
      <origin
        xyz="0.11272586814418 -2.36892283567158E-10 -8.1158884057686E-09"
        rpy="0 0 0" />
      <mass
        value="687" />
      <inertia
        ixx="0.543225099799896"
        ixy="-8.61710857123481E-10"
        ixz="-7.15020228924521E-09"
        iyy="0.665639778776312"
        iyz="-7.52324691710715E-08"
        izz="0.665642767549907" />
    </inertial>
    <visual>
      <origin
        xyz="0 0 0"
        rpy="0 0 0" />
      <geometry>
        <mesh
          filename="package://ivt_assem_kinema1/meshes/L8(EE-TC).STL" />
      </geometry>
      <material
        name="">
        <color
          rgba="1 0 1 1" />
      </material>
    </visual>
    <collision>
      <origin
        xyz="0 0 0"
        rpy="0 0 0" />
      <geometry>
        <mesh
          filename="package://ivt_assem_kinema1/meshes/L8(EE-TC).STL" />
      </geometry>
    </collision>
  </link>
  <joint
    name="J78"
    type="revolute">
    <origin
      xyz="0 0 0"
      rpy="-2.50395585744372 0 0" />
    <parent
      link="L7(EE-Tool)" />
    <child
      link="L8(EE-TC)" />
    <axis
      xyz="1 0 0" />
    <limit
      lower="-4.36332"
      upper="4.36332"
      effort="0"
      velocity="0" />
      <!-- lower="-2.1817", upper="2.1817"-->
      <!-- extended: lower="-4.36332", upper="4.36332"-->
  </joint>
  <link
    name="L9(Dummy-TC)">
    <inertial>
      <origin
        xyz="1.99840144432528E-15 -8.88178419700125E-16 -0.0750000000014303"
        rpy="0 0 0" />
      <mass
        value="1.0" />
      <inertia
        ixx="0.969107285311859"
        ixy="-2.6727647100922E-48"
        ixz="1.50119634696304E-33"
        iyy="0.969107285311859"
        iyz="-1.75339909336584E-33"
        izz="1.78442870149198" />
    </inertial>
    <visual>
      <origin
        xyz="0 0 0"
        rpy="0 0 0" />
      <geometry>
        <mesh
          filename="package://ivt_assem_kinema1/meshes/L9(Dummy-TC).STL" />
      </geometry>
      <material
        name="">
        <color
          rgba="0.8 0.8 0.8 1" />
      </material>
    </visual>
    <collision>
      <origin
        xyz="0 0 0"
        rpy="0 0 0" />
      <geometry>
        <mesh
          filename="package://ivt_assem_kinema1/meshes/L9(Dummy-TC).STL" />
      </geometry>
    </collision>
  </link>
  <joint
    name="J89"
    type="fixed">
    <origin
      xyz="0.293 0 0"
      rpy="-1.5708 -1.0815 1.5708" />
    <!-- <origin
      xyz="0.293 0 0"
      rpy="-1.5708 -1.0815 1.5708" /> -->
    <parent
      link="L8(EE-TC)" />
    <child
      link="L9(Dummy-TC)" />
    <axis
      xyz="0 0 0" />
  </joint>
  <!-- <link name="L10(end-point)"/>
  <joint 
    name="J910" type="fixed">
    <origin rpy="0 0 0" xyz="0 0 0"/>
    <parent link="L9(Dummy-TC)"/>
    <child link="L10(end-point)"/>
    <axis xyz="0 0 0"/> 
  </joint> -->
</robot>
