Link validation passed.
	<link name="link_0">
		<visual>
			<geometry>
				<mesh filename=""/>
			</geometry>
		</visual>
		<collision>
			<geometry>
				<mesh filename=""/>
			</geometry>
		</collision>
		<inertial>
			<mass value="1.0"/>
			<inertia ixx="0.0" ixy="0.0" ixz="0.0" iyy="0.0" iyz="0.0" izz="0.0"/>
		</inertial>
	</link>

Link validation passed.
	<link name="link_1">
		<visual>
			<geometry>
				<mesh filename=""/>
			</geometry>
		</visual>
		<collision>
			<geometry>
				<mesh filename=""/>
			</geometry>
		</collision>
		<inertial>
			<mass value="1.0"/>
			<inertia ixx="0.0" ixy="0.0" ixz="0.0" iyy="0.0" iyz="0.0" izz="0.0"/>
		</inertial>
	</link>

Joint validation passed.
	<joint name="joint_0" type="revolute">
		<parent link="link_0"/>
		<child link="link_1"/>
		<origin xyz="9.184850993605148e-17 1.5 1.5" rpy="0.0 1.5707963267948966 1.5707963267948966"/>
		<axis xyz="0 0 1"/>
		<limit effort="100.0" lower="-3.141592653589793" upper="3.141592653589793" velocity="1.0"/>
		<dynamics damping="0.0" friction="0.0"/>
	</joint>

Link validation passed.
Link validation passed.
Mesh file generated: base_link.stl
Link validation passed.
Joint validation passed.
Link validation passed.
Mesh file generated: link_1.stl
Joint validation passed.
<?xml version="1.0" ?>
<robot name="test_robot">
	<link name="world"/>
	<joint name="world_joint" type="fixed">
		<parent link="world"/>
		<child link="base_link"/>
		<origin xyz="0.0 0.0 0.0" rpy="0.0 0.0 0.0"/>
		<axis xyz="0 0 1"/>
		<limit effort="100.0" lower="-3.141592653589793" upper="3.141592653589793" velocity="1.0"/>
		<dynamics damping="0.0" friction="0.0"/>
	</joint>
	<link name="base_link">
		<visual>
			<geometry>
				<mesh filename="base_link.stl"/>
			</geometry>
		</visual>
		<collision>
			<geometry>
				<mesh filename="base_link.stl"/>
			</geometry>
		</collision>
		<inertial>
			<mass value="1.0"/>
			<inertia ixx="0.0" ixy="0.0" ixz="0.0" iyy="0.0" iyz="0.0" izz="0.0"/>
		</inertial>
	</link>
	<link name="link_1">
		<visual>
			<geometry>
				<mesh filename="link_1.stl"/>
			</geometry>
		</visual>
		<collision>
			<geometry>
				<mesh filename="link_1.stl"/>
			</geometry>
		</collision>
		<inertial>
			<mass value="1.0"/>
			<inertia ixx="0.0" ixy="0.0" ixz="0.0" iyy="0.0" iyz="0.0" izz="0.0"/>
		</inertial>
	</link>
	<joint name="joint_0" type="revolute">
		<parent link="base_link"/>
		<child link="link_1"/>
		<origin xyz="9.184850993605148e-17 1.5 6.5" rpy="0.0 1.5707963267948966 1.5707963267948966"/>
		<axis xyz="0 0 1"/>
		<limit effort="100.0" lower="-3.141592653589793" upper="3.141592653589793" velocity="1.0"/>
		<dynamics damping="0.0" friction="0.0"/>
	</joint>
</robot>
Link validation passed.
	<link name="link_0">
		<visual>
			<geometry>
				<mesh filename=""/>
			</geometry>
		</visual>
		<collision>
			<geometry>
				<mesh filename=""/>
			</geometry>
		</collision>
		<inertial>
			<mass value="1.0"/>
			<inertia ixx="0.0" ixy="0.0" ixz="0.0" iyy="0.0" iyz="0.0" izz="0.0"/>
		</inertial>
	</link>

Link validation passed.
	<link name="link_1">
		<visual>
			<geometry>
				<mesh filename=""/>
			</geometry>
		</visual>
		<collision>
			<geometry>
				<mesh filename=""/>
			</geometry>
		</collision>
		<inertial>
			<mass value="1.0"/>
			<inertia ixx="0.0" ixy="0.0" ixz="0.0" iyy="0.0" iyz="0.0" izz="0.0"/>
		</inertial>
	</link>

Joint validation passed.
	<joint name="joint_0" type="revolute">
		<parent link="link_0"/>
		<child link="link_1"/>
		<origin xyz="9.184850993605148e-17 1.5 1.5" rpy="0.0 1.5707963267948966 1.5707963267948966"/>
		<axis xyz="0 0 1"/>
		<limit effort="100.0" lower="-3.141592653589793" upper="3.141592653589793" velocity="1.0"/>
		<dynamics damping="0.0" friction="0.0"/>
	</joint>

Link validation passed.
Link validation passed.
Mesh file generated: base_link.stl
Link validation passed.
Joint validation passed.
Link validation passed.
Mesh file generated: link_1.stl
Joint validation passed.
<?xml version="1.0" ?>
<robot name="test_robot">
	<link name="world"/>
	<joint name="world_joint" type="fixed">
		<parent link="world"/>
		<child link="base_link"/>
		<origin xyz="0.0 0.0 0.0" rpy="0.0 0.0 0.0"/>
		<axis xyz="0 0 1"/>
		<limit effort="100.0" lower="-3.141592653589793" upper="3.141592653589793" velocity="1.0"/>
		<dynamics damping="0.0" friction="0.0"/>
	</joint>
	<link name="base_link">
		<visual>
			<geometry>
				<mesh filename="base_link.stl"/>
			</geometry>
		</visual>
		<collision>
			<geometry>
				<mesh filename="base_link.stl"/>
			</geometry>
		</collision>
		<inertial>
			<mass value="1.0"/>
			<inertia ixx="0.0" ixy="0.0" ixz="0.0" iyy="0.0" iyz="0.0" izz="0.0"/>
		</inertial>
	</link>
	<link name="link_1">
		<visual>
			<geometry>
				<mesh filename="link_1.stl"/>
			</geometry>
		</visual>
		<collision>
			<geometry>
				<mesh filename="link_1.stl"/>
			</geometry>
		</collision>
		<inertial>
			<mass value="1.0"/>
			<inertia ixx="0.0" ixy="0.0" ixz="0.0" iyy="0.0" iyz="0.0" izz="0.0"/>
		</inertial>
	</link>
	<joint name="joint_0" type="revolute">
		<parent link="base_link"/>
		<child link="link_1"/>
		<origin xyz="9.184850993605148e-17 1.5 6.5" rpy="0.0 1.5707963267948966 1.5707963267948966"/>
		<axis xyz="0 0 1"/>
		<limit effort="100.0" lower="-3.141592653589793" upper="3.141592653589793" velocity="1.0"/>
		<dynamics damping="0.0" friction="0.0"/>
	</joint>
</robot>
Link validation passed.
	<link name="link_0">
		<visual>
			<geometry>
				<mesh filename=""/>
			</geometry>
		</visual>
		<collision>
			<geometry>
				<mesh filename=""/>
			</geometry>
		</collision>
		<inertial>
			<mass value="1.0"/>
			<inertia ixx="0.0" ixy="0.0" ixz="0.0" iyy="0.0" iyz="0.0" izz="0.0"/>
		</inertial>
	</link>

Link validation passed.
	<link name="link_1">
		<visual>
			<geometry>
				<mesh filename=""/>
			</geometry>
		</visual>
		<collision>
			<geometry>
				<mesh filename=""/>
			</geometry>
		</collision>
		<inertial>
			<mass value="1.0"/>
			<inertia ixx="0.0" ixy="0.0" ixz="0.0" iyy="0.0" iyz="0.0" izz="0.0"/>
		</inertial>
	</link>

Joint validation passed.
	<joint name="joint_0" type="revolute">
		<parent link="link_0"/>
		<child link="link_1"/>
		<origin xyz="9.184850993605148e-17 1.5 1.5" rpy="0.0 1.5707963267948966 1.5707963267948966"/>
		<axis xyz="0 0 1"/>
		<limit effort="100.0" lower="-3.141592653589793" upper="3.141592653589793" velocity="1.0"/>
		<dynamics damping="0.0" friction="0.0"/>
	</joint>

Link validation passed.
Link validation passed.
Mesh file generated: base_link.stl
Link validation passed.
Joint validation passed.
Link validation passed.
Mesh file generated: link_1.stl
Joint validation passed.
<?xml version="1.0" ?>
<robot name="test_robot">
	<link name="world"/>
	<joint name="world_joint" type="fixed">
		<parent link="world"/>
		<child link="base_link"/>
		<origin xyz="0.0 0.0 0.0" rpy="0.0 0.0 0.0"/>
		<axis xyz="0 0 1"/>
		<limit effort="100.0" lower="-3.141592653589793" upper="3.141592653589793" velocity="1.0"/>
		<dynamics damping="0.0" friction="0.0"/>
	</joint>
	<link name="base_link">
		<visual>
			<geometry>
				<mesh filename="base_link.stl"/>
			</geometry>
		</visual>
		<collision>
			<geometry>
				<mesh filename="base_link.stl"/>
			</geometry>
		</collision>
		<inertial>
			<mass value="1.0"/>
			<inertia ixx="0.0" ixy="0.0" ixz="0.0" iyy="0.0" iyz="0.0" izz="0.0"/>
		</inertial>
	</link>
	<link name="link_1">
		<visual>
			<geometry>
				<mesh filename="link_1.stl"/>
			</geometry>
		</visual>
		<collision>
			<geometry>
				<mesh filename="link_1.stl"/>
			</geometry>
		</collision>
		<inertial>
			<mass value="1.0"/>
			<inertia ixx="0.0" ixy="0.0" ixz="0.0" iyy="0.0" iyz="0.0" izz="0.0"/>
		</inertial>
	</link>
	<joint name="joint_0" type="revolute">
		<parent link="base_link"/>
		<child link="link_1"/>
		<origin xyz="1.5 0.0 6.5" rpy="0.0 1.5707963267948966 0.0"/>
		<axis xyz="0 0 1"/>
		<limit effort="100.0" lower="-3.141592653589793" upper="3.141592653589793" velocity="1.0"/>
		<dynamics damping="0.0" friction="0.0"/>
	</joint>
</robot>
Link validation passed.
	<link name="link_0">
		<visual>
			<geometry>
				<mesh filename=""/>
			</geometry>
		</visual>
		<collision>
			<geometry>
				<mesh filename=""/>
			</geometry>
		</collision>
		<inertial>
			<mass value="1.0"/>
			<inertia ixx="0.0" ixy="0.0" ixz="0.0" iyy="0.0" iyz="0.0" izz="0.0"/>
		</inertial>
	</link>

Link validation passed.
	<link name="link_1">
		<visual>
			<geometry>
				<mesh filename=""/>
			</geometry>
		</visual>
		<collision>
			<geometry>
				<mesh filename=""/>
			</geometry>
		</collision>
		<inertial>
			<mass value="1.0"/>
			<inertia ixx="0.0" ixy="0.0" ixz="0.0" iyy="0.0" iyz="0.0" izz="0.0"/>
		</inertial>
	</link>

Joint validation passed.
	<joint name="joint_0" type="revolute">
		<parent link="link_0"/>
		<child link="link_1"/>
		<origin xyz="9.184850993605148e-17 1.5 1.5" rpy="0.0 1.5707963267948966 1.5707963267948966"/>
		<axis xyz="0 0 1"/>
		<limit effort="100.0" lower="-3.141592653589793" upper="3.141592653589793" velocity="1.0"/>
		<dynamics damping="0.0" friction="0.0"/>
	</joint>

Link validation passed.
Link validation passed.
Mesh file generated: base_link.stl
Link validation passed.
Joint validation passed.
Link validation passed.
Mesh file generated: link_1.stl
Joint validation passed.
Link validation passed.
Mesh file generated: link_2.stl
Joint validation passed.
<?xml version="1.0" ?>
<robot name="test_robot">
	<link name="world"/>
	<joint name="world_joint" type="fixed">
		<parent link="world"/>
		<child link="base_link"/>
		<origin xyz="0.0 0.0 0.0" rpy="0.0 0.0 0.0"/>
		<axis xyz="0 0 1"/>
		<limit effort="100.0" lower="-3.141592653589793" upper="3.141592653589793" velocity="1.0"/>
		<dynamics damping="0.0" friction="0.0"/>
	</joint>
	<link name="base_link">
		<visual>
			<geometry>
				<mesh filename="base_link.stl"/>
			</geometry>
		</visual>
		<collision>
			<geometry>
				<mesh filename="base_link.stl"/>
			</geometry>
		</collision>
		<inertial>
			<mass value="1.0"/>
			<inertia ixx="0.0" ixy="0.0" ixz="0.0" iyy="0.0" iyz="0.0" izz="0.0"/>
		</inertial>
	</link>
	<link name="link_1">
		<visual>
			<geometry>
				<mesh filename="link_1.stl"/>
			</geometry>
		</visual>
		<collision>
			<geometry>
				<mesh filename="link_1.stl"/>
			</geometry>
		</collision>
		<inertial>
			<mass value="1.0"/>
			<inertia ixx="0.0" ixy="0.0" ixz="0.0" iyy="0.0" iyz="0.0" izz="0.0"/>
		</inertial>
	</link>
	<joint name="joint_0" type="revolute">
		<parent link="base_link"/>
		<child link="link_1"/>
		<origin xyz="1.5 0.0 6.5" rpy="0.0 1.5707963267948966 0.0"/>
		<axis xyz="0 0 1"/>
		<limit effort="100.0" lower="-3.141592653589793" upper="3.141592653589793" velocity="1.0"/>
		<dynamics damping="0.0" friction="0.0"/>
	</joint>
	<link name="link_2">
		<visual>
			<geometry>
				<mesh filename="link_2.stl"/>
			</geometry>
		</visual>
		<collision>
			<geometry>
				<mesh filename="link_2.stl"/>
			</geometry>
		</collision>
		<inertial>
			<mass value="1.0"/>
			<inertia ixx="0.0" ixy="0.0" ixz="0.0" iyy="0.0" iyz="0.0" izz="0.0"/>
		</inertial>
	</link>
	<joint name="joint_1" type="revolute">
		<parent link="link_1"/>
		<child link="link_2"/>
		<origin xyz="-1.5 1.8369701987210297e-16 1.5" rpy="0.0 1.5707963267948966 3.141592653589793"/>
		<axis xyz="0 0 1"/>
		<limit effort="100.0" lower="-3.141592653589793" upper="3.141592653589793" velocity="1.0"/>
		<dynamics damping="0.0" friction="0.0"/>
	</joint>
</robot>
Link validation passed.
	<link name="link_0">
		<visual>
			<geometry>
				<mesh filename=""/>
			</geometry>
		</visual>
		<collision>
			<geometry>
				<mesh filename=""/>
			</geometry>
		</collision>
		<inertial>
			<mass value="1.0"/>
			<inertia ixx="0.0" ixy="0.0" ixz="0.0" iyy="0.0" iyz="0.0" izz="0.0"/>
		</inertial>
	</link>

Link validation passed.
	<link name="link_1">
		<visual>
			<geometry>
				<mesh filename=""/>
			</geometry>
		</visual>
		<collision>
			<geometry>
				<mesh filename=""/>
			</geometry>
		</collision>
		<inertial>
			<mass value="1.0"/>
			<inertia ixx="0.0" ixy="0.0" ixz="0.0" iyy="0.0" iyz="0.0" izz="0.0"/>
		</inertial>
	</link>

Joint validation passed.
	<joint name="joint_0" type="revolute">
		<parent link="link_0"/>
		<child link="link_1"/>
		<origin xyz="9.184850993605148e-17 1.5 1.5" rpy="0.0 1.5707963267948966 1.5707963267948966"/>
		<axis xyz="0 0 1"/>
		<limit effort="100.0" lower="-3.141592653589793" upper="3.141592653589793" velocity="1.0"/>
		<dynamics damping="0.0" friction="0.0"/>
	</joint>

Link validation passed.
Link validation passed.
Mesh file generated: base_link.stl
Link validation passed.
Joint validation passed.
Link validation passed.
Mesh file generated: link_1.stl
Joint validation passed.
Link validation passed.
Mesh file generated: link_2.stl
Joint validation passed.
Link validation passed.
Mesh file generated: link_3.stl
Joint validation passed.
<?xml version="1.0" ?>
<robot name="test_robot">
	<link name="world"/>
	<joint name="world_joint" type="fixed">
		<parent link="world"/>
		<child link="base_link"/>
		<origin xyz="0.0 0.0 0.0" rpy="0.0 0.0 0.0"/>
		<axis xyz="0 0 1"/>
		<limit effort="100.0" lower="-3.141592653589793" upper="3.141592653589793" velocity="1.0"/>
		<dynamics damping="0.0" friction="0.0"/>
	</joint>
	<link name="base_link">
		<visual>
			<geometry>
				<mesh filename="base_link.stl"/>
			</geometry>
		</visual>
		<collision>
			<geometry>
				<mesh filename="base_link.stl"/>
			</geometry>
		</collision>
		<inertial>
			<mass value="1.0"/>
			<inertia ixx="0.0" ixy="0.0" ixz="0.0" iyy="0.0" iyz="0.0" izz="0.0"/>
		</inertial>
	</link>
	<link name="link_1">
		<visual>
			<geometry>
				<mesh filename="link_1.stl"/>
			</geometry>
		</visual>
		<collision>
			<geometry>
				<mesh filename="link_1.stl"/>
			</geometry>
		</collision>
		<inertial>
			<mass value="1.0"/>
			<inertia ixx="0.0" ixy="0.0" ixz="0.0" iyy="0.0" iyz="0.0" izz="0.0"/>
		</inertial>
	</link>
	<joint name="joint_0" type="revolute">
		<parent link="base_link"/>
		<child link="link_1"/>
		<origin xyz="1.5 0.0 6.5" rpy="0.0 1.5707963267948966 0.0"/>
		<axis xyz="0 0 1"/>
		<limit effort="100.0" lower="-3.141592653589793" upper="3.141592653589793" velocity="1.0"/>
		<dynamics damping="0.0" friction="0.0"/>
	</joint>
	<link name="link_2">
		<visual>
			<geometry>
				<mesh filename="link_2.stl"/>
			</geometry>
		</visual>
		<collision>
			<geometry>
				<mesh filename="link_2.stl"/>
			</geometry>
		</collision>
		<inertial>
			<mass value="1.0"/>
			<inertia ixx="0.0" ixy="0.0" ixz="0.0" iyy="0.0" iyz="0.0" izz="0.0"/>
		</inertial>
	</link>
	<joint name="joint_1" type="revolute">
		<parent link="link_1"/>
		<child link="link_2"/>
		<origin xyz="-1.5 1.8369701987210297e-16 1.5" rpy="0.0 1.5707963267948966 3.141592653589793"/>
		<axis xyz="0 0 1"/>
		<limit effort="100.0" lower="-3.141592653589793" upper="3.141592653589793" velocity="1.0"/>
		<dynamics damping="0.0" friction="0.0"/>
	</joint>
	<link name="link_3">
		<visual>
			<geometry>
				<mesh filename="link_3.stl"/>
			</geometry>
		</visual>
		<collision>
			<geometry>
				<mesh filename="link_3.stl"/>
			</geometry>
		</collision>
		<inertial>
			<mass value="1.0"/>
			<inertia ixx="0.0" ixy="0.0" ixz="0.0" iyy="0.0" iyz="0.0" izz="0.0"/>
		</inertial>
	</link>
	<joint name="joint_2" type="revolute">
		<parent link="link_2"/>
		<child link="link_3"/>
		<origin xyz="1.5 0.0 6.5" rpy="0.0 1.5707963267948966 0.0"/>
		<axis xyz="0 0 1"/>
		<limit effort="100.0" lower="-3.141592653589793" upper="3.141592653589793" velocity="1.0"/>
		<dynamics damping="0.0" friction="0.0"/>
	</joint>
</robot>
Link validation passed.
	<link name="link_0">
		<visual>
			<geometry>
				<mesh filename=""/>
			</geometry>
		</visual>
		<collision>
			<geometry>
				<mesh filename=""/>
			</geometry>
		</collision>
		<inertial>
			<mass value="1.0"/>
			<inertia ixx="0.0" ixy="0.0" ixz="0.0" iyy="0.0" iyz="0.0" izz="0.0"/>
		</inertial>
	</link>

Link validation passed.
	<link name="link_1">
		<visual>
			<geometry>
				<mesh filename=""/>
			</geometry>
		</visual>
		<collision>
			<geometry>
				<mesh filename=""/>
			</geometry>
		</collision>
		<inertial>
			<mass value="1.0"/>
			<inertia ixx="0.0" ixy="0.0" ixz="0.0" iyy="0.0" iyz="0.0" izz="0.0"/>
		</inertial>
	</link>

Joint validation passed.
	<joint name="joint_0" type="revolute">
		<parent link="link_0"/>
		<child link="link_1"/>
		<origin xyz="9.184850993605148e-17 1.5 1.5" rpy="0.0 1.5707963267948966 1.5707963267948966"/>
		<axis xyz="0 0 1"/>
		<limit effort="100.0" lower="-3.141592653589793" upper="3.141592653589793" velocity="1.0"/>
		<dynamics damping="0.0" friction="0.0"/>
	</joint>

Link validation passed.
Link validation passed.
Mesh file generated: base_link.stl
Link validation passed.
Joint validation passed.
Link validation passed.
Mesh file generated: link_1.stl
Joint validation passed.
Link validation passed.
Mesh file generated: link_2.stl
Joint validation passed.
Link validation passed.
Mesh file generated: link_3.stl
Joint validation passed.
Link validation passed.
Mesh file generated: link_4.stl
Joint validation passed.
<?xml version="1.0" ?>
<robot name="test_robot">
	<link name="world"/>
	<joint name="world_joint" type="fixed">
		<parent link="world"/>
		<child link="base_link"/>
		<origin xyz="0.0 0.0 0.0" rpy="0.0 0.0 0.0"/>
		<axis xyz="0 0 1"/>
		<limit effort="100.0" lower="-3.141592653589793" upper="3.141592653589793" velocity="1.0"/>
		<dynamics damping="0.0" friction="0.0"/>
	</joint>
	<link name="base_link">
		<visual>
			<geometry>
				<mesh filename="base_link.stl"/>
			</geometry>
		</visual>
		<collision>
			<geometry>
				<mesh filename="base_link.stl"/>
			</geometry>
		</collision>
		<inertial>
			<mass value="1.0"/>
			<inertia ixx="0.0" ixy="0.0" ixz="0.0" iyy="0.0" iyz="0.0" izz="0.0"/>
		</inertial>
	</link>
	<link name="link_1">
		<visual>
			<geometry>
				<mesh filename="link_1.stl"/>
			</geometry>
		</visual>
		<collision>
			<geometry>
				<mesh filename="link_1.stl"/>
			</geometry>
		</collision>
		<inertial>
			<mass value="1.0"/>
			<inertia ixx="0.0" ixy="0.0" ixz="0.0" iyy="0.0" iyz="0.0" izz="0.0"/>
		</inertial>
	</link>
	<joint name="joint_0" type="revolute">
		<parent link="base_link"/>
		<child link="link_1"/>
		<origin xyz="1.5 0.0 6.5" rpy="0.0 1.5707963267948966 0.0"/>
		<axis xyz="0 0 1"/>
		<limit effort="100.0" lower="-3.141592653589793" upper="3.141592653589793" velocity="1.0"/>
		<dynamics damping="0.0" friction="0.0"/>
	</joint>
	<link name="link_2">
		<visual>
			<geometry>
				<mesh filename="link_2.stl"/>
			</geometry>
		</visual>
		<collision>
			<geometry>
				<mesh filename="link_2.stl"/>
			</geometry>
		</collision>
		<inertial>
			<mass value="1.0"/>
			<inertia ixx="0.0" ixy="0.0" ixz="0.0" iyy="0.0" iyz="0.0" izz="0.0"/>
		</inertial>
	</link>
	<joint name="joint_1" type="revolute">
		<parent link="link_1"/>
		<child link="link_2"/>
		<origin xyz="-1.5 1.8369701987210297e-16 1.5" rpy="0.0 1.5707963267948966 3.141592653589793"/>
		<axis xyz="0 0 1"/>
		<limit effort="100.0" lower="-3.141592653589793" upper="3.141592653589793" velocity="1.0"/>
		<dynamics damping="0.0" friction="0.0"/>
	</joint>
	<link name="link_3">
		<visual>
			<geometry>
				<mesh filename="link_3.stl"/>
			</geometry>
		</visual>
		<collision>
			<geometry>
				<mesh filename="link_3.stl"/>
			</geometry>
		</collision>
		<inertial>
			<mass value="1.0"/>
			<inertia ixx="0.0" ixy="0.0" ixz="0.0" iyy="0.0" iyz="0.0" izz="0.0"/>
		</inertial>
	</link>
	<joint name="joint_2" type="revolute">
		<parent link="link_2"/>
		<child link="link_3"/>
		<origin xyz="1.5 0.0 6.5" rpy="0.0 1.5707963267948966 0.0"/>
		<axis xyz="0 0 1"/>
		<limit effort="100.0" lower="-3.141592653589793" upper="3.141592653589793" velocity="1.0"/>
		<dynamics damping="0.0" friction="0.0"/>
	</joint>
	<link name="link_4">
		<visual>
			<geometry>
				<mesh filename="link_4.stl"/>
			</geometry>
		</visual>
		<collision>
			<geometry>
				<mesh filename="link_4.stl"/>
			</geometry>
		</collision>
		<inertial>
			<mass value="1.0"/>
			<inertia ixx="0.0" ixy="0.0" ixz="0.0" iyy="0.0" iyz="0.0" izz="0.0"/>
		</inertial>
	</link>
	<joint name="joint_3" type="revolute">
		<parent link="link_3"/>
		<child link="link_4"/>
		<origin xyz="-1.5 1.8369701987210297e-16 1.5" rpy="0.0 1.5707963267948966 3.141592653589793"/>
		<axis xyz="0 0 1"/>
		<limit effort="100.0" lower="-3.141592653589793" upper="3.141592653589793" velocity="1.0"/>
		<dynamics damping="0.0" friction="0.0"/>
	</joint>
</robot>
Link validation passed.
Link validation passed.
Mesh file generated: base_link.stl
Link validation passed.
Joint validation passed.
Link validation passed.
Mesh file generated: link_1.stl
Joint validation passed.
Link validation passed.
Mesh file generated: link_2.stl
Joint validation passed.
Link validation passed.
Mesh file generated: link_3.stl
Joint validation passed.
Link validation passed.
Mesh file generated: link_4.stl
Joint validation passed.
<?xml version="1.0" ?>
<robot name="test_robot">
	<link name="world"/>
	<joint name="world_joint" type="fixed">
		<parent link="world"/>
		<child link="base_link"/>
		<origin xyz="0.0 0.0 0.0" rpy="0.0 0.0 0.0"/>
		<axis xyz="0 0 1"/>
		<limit effort="100.0" lower="-3.141592653589793" upper="3.141592653589793" velocity="1.0"/>
		<dynamics damping="0.0" friction="0.0"/>
	</joint>
	<link name="base_link">
		<visual>
			<geometry>
				<mesh filename="base_link.stl"/>
			</geometry>
		</visual>
		<collision>
			<geometry>
				<mesh filename="base_link.stl"/>
			</geometry>
		</collision>
		<inertial>
			<mass value="1.0"/>
			<inertia ixx="0.0" ixy="0.0" ixz="0.0" iyy="0.0" iyz="0.0" izz="0.0"/>
		</inertial>
	</link>
	<link name="link_1">
		<visual>
			<geometry>
				<mesh filename="link_1.stl"/>
			</geometry>
		</visual>
		<collision>
			<geometry>
				<mesh filename="link_1.stl"/>
			</geometry>
		</collision>
		<inertial>
			<mass value="1.0"/>
			<inertia ixx="0.0" ixy="0.0" ixz="0.0" iyy="0.0" iyz="0.0" izz="0.0"/>
		</inertial>
	</link>
	<joint name="joint_0" type="revolute">
		<parent link="base_link"/>
		<child link="link_1"/>
		<origin xyz="1.5 0.0 8.5" rpy="0.0 1.5707963267948966 0.0"/>
		<axis xyz="0 0 1"/>
		<limit effort="100.0" lower="-3.141592653589793" upper="3.141592653589793" velocity="1.0"/>
		<dynamics damping="0.0" friction="0.0"/>
	</joint>
	<link name="link_2">
		<visual>
			<geometry>
				<mesh filename="link_2.stl"/>
			</geometry>
		</visual>
		<collision>
			<geometry>
				<mesh filename="link_2.stl"/>
			</geometry>
		</collision>
		<inertial>
			<mass value="1.0"/>
			<inertia ixx="0.0" ixy="0.0" ixz="0.0" iyy="0.0" iyz="0.0" izz="0.0"/>
		</inertial>
	</link>
	<joint name="joint_1" type="revolute">
		<parent link="link_1"/>
		<child link="link_2"/>
		<origin xyz="-1.5 1.8369701987210297e-16 1.5" rpy="0.0 1.5707963267948966 3.141592653589793"/>
		<axis xyz="0 0 1"/>
		<limit effort="100.0" lower="-3.141592653589793" upper="3.141592653589793" velocity="1.0"/>
		<dynamics damping="0.0" friction="0.0"/>
	</joint>
	<link name="link_3">
		<visual>
			<geometry>
				<mesh filename="link_3.stl"/>
			</geometry>
		</visual>
		<collision>
			<geometry>
				<mesh filename="link_3.stl"/>
			</geometry>
		</collision>
		<inertial>
			<mass value="1.0"/>
			<inertia ixx="0.0" ixy="0.0" ixz="0.0" iyy="0.0" iyz="0.0" izz="0.0"/>
		</inertial>
	</link>
	<joint name="joint_2" type="revolute">
		<parent link="link_2"/>
		<child link="link_3"/>
		<origin xyz="1.5 0.0 6.5" rpy="0.0 1.5707963267948966 0.0"/>
		<axis xyz="0 0 1"/>
		<limit effort="100.0" lower="-3.141592653589793" upper="3.141592653589793" velocity="1.0"/>
		<dynamics damping="0.0" friction="0.0"/>
	</joint>
	<link name="link_4">
		<visual>
			<geometry>
				<mesh filename="link_4.stl"/>
			</geometry>
		</visual>
		<collision>
			<geometry>
				<mesh filename="link_4.stl"/>
			</geometry>
		</collision>
		<inertial>
			<mass value="1.0"/>
			<inertia ixx="0.0" ixy="0.0" ixz="0.0" iyy="0.0" iyz="0.0" izz="0.0"/>
		</inertial>
	</link>
	<joint name="joint_3" type="revolute">
		<parent link="link_3"/>
		<child link="link_4"/>
		<origin xyz="-1.5 1.8369701987210297e-16 1.5" rpy="0.0 1.5707963267948966 3.141592653589793"/>
		<axis xyz="0 0 1"/>
		<limit effort="100.0" lower="-3.141592653589793" upper="3.141592653589793" velocity="1.0"/>
		<dynamics damping="0.0" friction="0.0"/>
	</joint>
</robot>
